2025-10-06 15:43:38,029 [INFO] INFO:root:=== Script run_deep_search.py started ===
2025-10-06 15:43:38,029 [INFO] INFO:root:Logs are being written asynchronously to: /home/lars_lenon/CODING/Deep-Search-with-Agno/logs/run_deep_search_2025-10-06_15-43-38.log
2025-10-06 15:43:39,122 [INFO] INFO:root:Initializing workflow...
2025-10-06 15:43:39,137 [INFO] INFO:root:Serving FastAPI app on http://localhost:8001 (reload=False)
2025-10-06 15:43:40,228 [INFO] INFO:httpx:HTTP Request: POST https://api.agno.com/v2/apps "HTTP/1.1 202 Accepted"
2025-10-06 15:43:40,238 [INFO] INFO:root:[34mINFO[0m Starting API on localhost:[1;36m8001[0m
2025-10-06 15:43:40,239 [ERROR] ERROR:root:An error occurred during FastAPI workflow setup: Unable to configure formatter 'default'
Traceback (most recent call last):
  File "/home/lars_lenon/.local/share/uv/python/cpython-3.13.7-linux-x86_64-gnu/lib/python3.13/logging/config.py", line 583, in configure
    formatters[name] = self.configure_formatter(
                       ~~~~~~~~~~~~~~~~~~~~~~~~^
                                        formatters[name])
                                        ^^^^^^^^^^^^^^^^^
  File "/home/lars_lenon/.local/share/uv/python/cpython-3.13.7-linux-x86_64-gnu/lib/python3.13/logging/config.py", line 693, in configure_formatter
    result = self.configure_custom(config)
  File "/home/lars_lenon/.local/share/uv/python/cpython-3.13.7-linux-x86_64-gnu/lib/python3.13/logging/config.py", line 487, in configure_custom
    result = c(**kwargs)
  File "/home/lars_lenon/CODING/Deep-Search-with-Agno/.venv/lib/python3.13/site-packages/uvicorn/logging.py", line 42, in __init__
    self.use_colors = sys.stdout.isatty()
                      ^^^^^^^^^^^^^^^^^
AttributeError: 'LoggerWriter' object has no attribute 'isatty'

The above exception was the direct cause of the following exception:

Traceback (most recent call last):
  File "/home/lars_lenon/CODING/Deep-Search-with-Agno/scripts/run_fastapi_deep_search.py", line 174, in <module>
    fastapi_app.serve(app=app, host=args.host, port=args.port, reload=args.reload)
    ~~~~~~~~~~~~~~~~~^^^^^^^^^^^^^^^^^^^^^^^^^^^^^^^^^^^^^^^^^^^^^^^^^^^^^^^^^^^^^
  File "/home/lars_lenon/CODING/Deep-Search-with-Agno/.venv/lib/python3.13/site-packages/agno/app/fastapi/app.py", line 105, in serve
    uvicorn.run(app=app, host=host, port=port, reload=reload, **kwargs)
    ~~~~~~~~~~~^^^^^^^^^^^^^^^^^^^^^^^^^^^^^^^^^^^^^^^^^^^^^^^^^^^^^^^^
  File "/home/lars_lenon/CODING/Deep-Search-with-Agno/.venv/lib/python3.13/site-packages/uvicorn/main.py", line 529, in run
    config = Config(
        app,
    ...<45 lines>...
        h11_max_incomplete_event_size=h11_max_incomplete_event_size,
    )
  File "/home/lars_lenon/CODING/Deep-Search-with-Agno/.venv/lib/python3.13/site-packages/uvicorn/config.py", line 277, in __init__
    self.configure_logging()
    ~~~~~~~~~~~~~~~~~~~~~~^^
  File "/home/lars_lenon/CODING/Deep-Search-with-Agno/.venv/lib/python3.13/site-packages/uvicorn/config.py", line 369, in configure_logging
    logging.config.dictConfig(self.log_config)
    ~~~~~~~~~~~~~~~~~~~~~~~~~^^^^^^^^^^^^^^^^^
  File "/home/lars_lenon/.local/share/uv/python/cpython-3.13.7-linux-x86_64-gnu/lib/python3.13/logging/config.py", line 935, in dictConfig
    dictConfigClass(config).configure()
    ~~~~~~~~~~~~~~~~~~~~~~~~~~~~~~~~~^^
  File "/home/lars_lenon/.local/share/uv/python/cpython-3.13.7-linux-x86_64-gnu/lib/python3.13/logging/config.py", line 586, in configure
    raise ValueError('Unable to configure '
                     'formatter %r' % name) from e
ValueError: Unable to configure formatter 'default'
2025-10-06 15:43:40,244 [ERROR] ERROR:root:Uncaught exception
Traceback (most recent call last):
  File "/home/lars_lenon/.local/share/uv/python/cpython-3.13.7-linux-x86_64-gnu/lib/python3.13/logging/config.py", line 583, in configure
    formatters[name] = self.configure_formatter(
                       ~~~~~~~~~~~~~~~~~~~~~~~~^
                                        formatters[name])
                                        ^^^^^^^^^^^^^^^^^
  File "/home/lars_lenon/.local/share/uv/python/cpython-3.13.7-linux-x86_64-gnu/lib/python3.13/logging/config.py", line 693, in configure_formatter
    result = self.configure_custom(config)
  File "/home/lars_lenon/.local/share/uv/python/cpython-3.13.7-linux-x86_64-gnu/lib/python3.13/logging/config.py", line 487, in configure_custom
    result = c(**kwargs)
  File "/home/lars_lenon/CODING/Deep-Search-with-Agno/.venv/lib/python3.13/site-packages/uvicorn/logging.py", line 42, in __init__
    self.use_colors = sys.stdout.isatty()
                      ^^^^^^^^^^^^^^^^^
AttributeError: 'LoggerWriter' object has no attribute 'isatty'

The above exception was the direct cause of the following exception:

Traceback (most recent call last):
  File "/home/lars_lenon/CODING/Deep-Search-with-Agno/scripts/run_fastapi_deep_search.py", line 174, in <module>
    fastapi_app.serve(app=app, host=args.host, port=args.port, reload=args.reload)
    ~~~~~~~~~~~~~~~~~^^^^^^^^^^^^^^^^^^^^^^^^^^^^^^^^^^^^^^^^^^^^^^^^^^^^^^^^^^^^^
  File "/home/lars_lenon/CODING/Deep-Search-with-Agno/.venv/lib/python3.13/site-packages/agno/app/fastapi/app.py", line 105, in serve
    uvicorn.run(app=app, host=host, port=port, reload=reload, **kwargs)
    ~~~~~~~~~~~^^^^^^^^^^^^^^^^^^^^^^^^^^^^^^^^^^^^^^^^^^^^^^^^^^^^^^^^
  File "/home/lars_lenon/CODING/Deep-Search-with-Agno/.venv/lib/python3.13/site-packages/uvicorn/main.py", line 529, in run
    config = Config(
        app,
    ...<45 lines>...
        h11_max_incomplete_event_size=h11_max_incomplete_event_size,
    )
  File "/home/lars_lenon/CODING/Deep-Search-with-Agno/.venv/lib/python3.13/site-packages/uvicorn/config.py", line 277, in __init__
    self.configure_logging()
    ~~~~~~~~~~~~~~~~~~~~~~^^
  File "/home/lars_lenon/CODING/Deep-Search-with-Agno/.venv/lib/python3.13/site-packages/uvicorn/config.py", line 369, in configure_logging
    logging.config.dictConfig(self.log_config)
    ~~~~~~~~~~~~~~~~~~~~~~~~~^^^^^^^^^^^^^^^^^
  File "/home/lars_lenon/.local/share/uv/python/cpython-3.13.7-linux-x86_64-gnu/lib/python3.13/logging/config.py", line 935, in dictConfig
    dictConfigClass(config).configure()
    ~~~~~~~~~~~~~~~~~~~~~~~~~~~~~~~~~^^
  File "/home/lars_lenon/.local/share/uv/python/cpython-3.13.7-linux-x86_64-gnu/lib/python3.13/logging/config.py", line 586, in configure
    raise ValueError('Unable to configure '
                     'formatter %r' % name) from e
ValueError: Unable to configure formatter 'default'
